<?xml version="1.0"?>
<robot name="wheel" xmlns:xacro="http://www.ros.org/wiki/xacro">
  <xacro:include filename="./inertial.urdf.xacro"/>

  <!-- Wheels -->
  <xacro:property name="wheel_mass" value="6.5" /> <!-- in kg-->
  
  <xacro:macro name="omni_wheel_geometry" params="wheel_height wheel_radius reflect">
    <origin xyz="0 0 0" rpy="0 0 0" />
    <geometry>
      <mesh filename="meshes/omni_wheel_${reflect}.dae" />
      <cylinder length="${wheel_height}" radius="${wheel_radius}" />
    </geometry>
  </xacro:macro>
  
  <xacro:macro name="omni_wheel" params="prefix parent *origin reflect wheel_height wheel_radius update_rate:=20">

    <joint name="${prefix}_wheel_joint" type="continuous">
      <parent link="${parent}"/>
      <child link="${prefix}_wheel_link"/>
      <xacro:insert_block name="origin" />
      <axis xyz="0 1 0" rpy="0 0 0" />
      <limit effort="100" velocity="100"/>
      <joint_properties damping="0.0" friction="0.0"/>
    </joint>

    <link name="${prefix}_wheel_link">
      <visual>
      <xacro:omni_wheel_geometry reflect="${reflect}" 
        wheel_height="${wheel_height}" 
        wheel_radius="${wheel_radius}" />
        <!-- <origin xyz="0 0 0" rpy="0 0 0" />
        <geometry>
          <mesh filename="file://$(find follow_me_robot)/meshes/omni_wheel_${reflect}.dae" />
        </geometry> -->
      </visual>

      <collision>
				<origin xyz="0 0 0" rpy="${pi/2} 0 0" />
        <geometry>
					<cylinder length="${wheel_height}" radius="${wheel_radius}" />
        </geometry>
      </collision>

      <inertial>
        <mass value="${wheel_mass}" />
        <origin xyz="0 0 0" />
        <xacro:solid_cylinder_inertia  m="${wheel_mass}" r="${wheel_radius}" h="${wheel_height}" />
      </inertial>
    </link>

    <!-- Transmission is important to link the joints and the controller (see robot_control/config/robot_control.yaml)-->
    <transmission name="${prefix}_wheel_joint_trans">
      <type>transmission_interface/SimpleTransmission</type>
      <joint name="${prefix}_wheel_joint" >
        <hardwareInterface>hardware_interface/VelocityJointInterface</hardwareInterface>
      </joint>
      <actuator name="${prefix}_wheel_joint_motor">
         <mechanicalReduction>1</mechanicalReduction>
      </actuator>
    </transmission>

    <gazebo reference="${prefix}_wheel_link">
		<mu1 value="1.0"/>
		<mu2 value="1.0"/>
		<kp value="10000000.0" />
		<kd value="1.0" />
		<fdir1 value="1 0 0"/>
        <turnGravityOff>false</turnGravityOff>
    </gazebo>
  
  </xacro:macro>
</robot>
